Workbook
Name OLE_LINK1: 'DR & Backup Matrix'!#REF!

Sheet Risk Matrix
A1: Business Continuity Risk Matrix
A2: The following table prioritizes threats by measuring the impact of the threat and identifying the probability of the threat. Consideration should be given to whether adequate preparations have been given to prevent or recover from these scenarios or whether the company is willing to accept the risk.
A4: This table was created as follows:
A5: 1. Impact is identified by company staff and is subjective with knowledge of the area. Impact is rated as (Severe = 5, Significant = 3, Manageable = 1) and assigned a numerical value.
A6: 2. Probability is identified by company staff and is subjective with knowledge of past experiences by threat type. Probability is rated as (Likely = 5, Possible =3, Unlikely = 1) and assigned a numerical value.
A7: 3. Risk factor is derived by the formula - Risk factor = Impact X Probability
A8: 4. Threat categories are malicious activity, natural disasters, technical disasters and pandemics. Threats are prioritized based on Risk Factor - highest to lowest. The Risk Factor ranking is subjective and imprecise with no significance to the ordering of risks that have the same Risk Factor number.
A10: Impact Severe=5 Significant=3 Manageable=1 | B10: Probability Likely=5 Possible=3 Unlikely=1 | C10: Risk Factor (Impact x Probability) | D10: Threat | E10: Category | F10: Worst Case Scenario
A11: 5 | B11: 5 | C11: =SUM(A11*B11) -> 25 | D11: Power Failure | E11: Technical Disaster | F11: Loss of power at the main/data center building for 5+ days.
A12: 5 | B12: 5 | C12: =SUM(A12*B12) -> 25 | D12: Internet or ISP Failure | E12: Technical Disaster | F12: No access to the internet from the primary internet provider for 5+ days.
A13: 5 | B13: 5 | C13: =SUM(A13*B13) -> 25 | D13: Hardware Failure | E13: Technical Disaster | F13: Critical hardware failure requiring hardware replacement.
A14: 5 | B14: 5 | C14: =SUM(A14*B14) -> 25 | D14: System or Application Software Failure | E14: Technical Disaster | F14: Critical business applications unavailable or functioning improperly for 5+ days.
A15: 5 | B15: 5 | C15: =SUM(A15*B15) -> 25 | D15: Telecom - Data Link Failure | E15: Technical Disaster | F15: Communications to service providers / other organization facilities is not operational for 5+ days.
A16: 5 | B16: 5 | C16: =SUM(A16*B16) -> 25 | D16: Gas Leak / Explosion | E16: Natural Disaster | F16: Severe damage or destruction of the main/data center building.
A17: 5 | B17: 5 | C17: =SUM(A17*B17) -> 25 | D17: Improper Handling of Sensitive Data | E17: Technical Disaster | F17: Customer data is exposed due to improper handling of data or lack of company policy. All customers have to be notified of the loss.
A18: 5 | B18: 3 | C18: =SUM(A18*B18) -> 15 | D18: Power/Generator Failure | E18: Technical Disaster | F18: Loss of power at the main/data center building for 5+ days. Backup generators fail.
A19: 3 | B19: 5 | C19: =SUM(A19*B19) -> 15 | D19: Embezzlement | E19: Malicious Activity | F19: Major loss of funds and severe damage to reputation.
A20: 3 | B20: 5 | C20: =SUM(A20*B20) -> 15 | D20: Employee Theft | E20: Malicious Activity | F20: Loss of significant funds due to employee theft.
A21: 5 | B21: 3 | C21: =SUM(A21*B21) -> 15 | D21: Unauthorized Modification or Malicious Damage to Hardware / Software | E21: Malicious Activity | F21: IT infrastructure component(s) unusable for 5+ days.
A22: 5 | B22: 3 | C22: =SUM(A22*B22) -> 15 | D22: Fire | E22: Natural Disaster | F22: The main/data center building is severely damaged or destroyed by fire.
... A46: 3 | B46: 1 | C46: =SUM(A46*B46) -> 3 | D46: Earthquake | E46: Natural Disaster | F46: Severe damage to or destruction of the main/data center building.

Sheet DR & Backup Matrix
A1: Protection Strategy | B1: Description | C1: Frequency / Storage | D1: Recovery Use
A2: Core - Outsourced to Fiserv
A3: The backup of the Core is the responsibility of Fiserv
A4: Virtual Servers
A5: All production servers are virtualized and replicated offsite. | B5: There are 10 production hosts in Chaska/KBSC to run the 150 virtual servers and 5 continuity hosts in Mpls/511. | C5: Daily replication to offsite. | D5: In the event of catastrophic failure to the production site, the 5 hosts will run the essential virtual servers until the production site can be recovered.
A6: VMWare is the manufacturer used for virtual machines | B6: Vsphere is the software used to manage all the virtual machines. | C6: Server 2008 template is available for creating new servers. | D6: Recovery of production servers takes up to 2 hours depending on the image size. Offsite the servers would take 2 - 3 hours to reset all DNS/DHCP, turn on and bring to most current update.
A7: Network Routers
A8: MPLS, Enventis, Fedline
A9: Network Switches & Controllers
A10: Each branch office has 1 switch and 1 phone controller | B10: There are 42 layer 3 network switches and 25 phone controllers at the various sites
A11: Perimeter Security Devices
A12: Dell Secureworks - iSensor IDS/IPS (2), Checkpoint Firewall (1), Zix e-mail (1), Mobile Iron (1)
A13: Network Servers
A14: VMWare VDPA is used for all virtual servers to restore data or images. | B14: Backup programs take snapshots periodically and scheduled backups nightly. | C14: Full backups intially and incrementals daily. | D14: Backups are stored on the data domain. The data domain is replicated offsite all day long. Virtual servers are replicated each day.
A15: SAN
A16: SAN | B16: VNEx is the SAN product. There are data stores within the SAN (20) groups of RAID hard drives. These replicate off to Mpls/511. | C16: The storage device is in Chaska/KBSC. Each office has their own domain controller. These are backed up every evening. The info on the storage VNEx is replicated offsite to Mpls/511 | D16: This is running all day long and is being sent all day to Mpls/511 via real time.
A17: Disaster and Backup Policy

Sheet System and Application Matrix
J1: System Recovery Strategy | L1: Data Recovery Option 1
A2: Recovery Priority | B2: System Name | C2: Application or Service | D2: Operating System | E2: Physical or Virtual | F2: RTO | G2: Recovery Time Capability | I2: RPO | J2: Within Production Site | K2: Across Site (511) | L2: Backup Frequency | M2: Data Recovery Program | N2: Local Data Recovery Option | O2: Across Site Recovery Option | P2: Recovery Point Capability | Q2: Production Location | R2: Recovery Location | S2: System or Technology Dependencies | T2: Data Classification (Confidential, Private, Public) | U2: Descriptions or Comments
B3: 360View | D3: MS Windows Server 2008R2 | E3: V | F3: 1 Day | G3: 3 Hours | J3: Create a new virtual server, restore from backup | K3: Would recover in 511. | N3: Backup snapshot | P3: 1 Day - would have to go back to previous days' data. | Q3: KBSC | R3: 511 | S3: Routers, Firewall, Switches, Active Directory | T3: Confidential
B4: AD** | C4: Multiple Domain Controllers for each branch to allow survivability | D4: MS Windows Server 2008R2 | E4: V | F4: 4 Hours | G4: 2 Hours | J4: All failover to each other and can authenticate to each other. A new one would be installed. | Q4: All offices | R4: Failover between sites | S4: Routers, Firewall, Switches | T4: Private
B5: APPS** | C5: Application servers | D5: MS Windows Server 2008R2 | E5: V | F5: 1 Day | G5: 1 Day | N5: Backup snapshot | Q5: KBSC | S5: Routers, Firewall, Switches, Active Directory | T5: Confidential
B6: BOLBDB2
B7: Business Analytics | C7: Viewpoint | D7: MS Windows Server 2008R2 | E7: V | F7: 4 Hours
B8: Business Online banking | C8: Web interface for online banking | D8: MS Windows Server 2008R2 | E8: V | F8: 6 Hours | G8: 2 Hours | J8: Create a new virtual server and restore from backup | K8: Server would be recovered in 511 | N8: No Data just web software | P8: None | Q8: KBSC | R8: 511 | S8: Routers, Firewall, Switches, Active Directory | T8: Confidential
B9: Centrix | D9: MS Windows Server 2008R2 | E9: V | F9: 4 Hours | G9: 4 hours | J9: Create a new virtual server, restore from backup | K9: Would recover the virtual server in 511. | N9: Backup snapshot | P9: 1 Day - would have to go back to previous days' data. | Q9: KBSC | R9: 511 | S9: Routers, Firewall, Switches, Active Directory | T9: Confidential
B10: CheckPoint Firewall | C10: Firewall | E10: V | F10: 4 Hours | G10: Failover | Q10: KBSC | R10: 511 | S10: Routers, Firewall | T10: N/A
B11: City Managed Router | C11: Ethernet (fiber) for the KBSC Data center | E11: P | F11: 4 Hours | G11: 2 Hours | J11: Would call city to install a new one | K11: Wouldn't recover in 511 | Q11: Chaska/KBSC | S11: Fiber Line | T11: N/A
B12: Copier or Printer Devices | C12: Printing, scanning | D12: Varies | E12: P | F12: 4 Hours | G12: 2 Hours | J12: Install new device | K12: Buy new device and install on server | N12: None | P12: N/A | Q12: All offices | R12: All offices | S12: Server | T12: N/A
B13: DD1 | C13: FTO Server (Part of Item Processing Cluster) - virtual printers | D13: Microsoft Vista | E13: P | F13: 3 Days | G13: 4 Hours - never recovered | J13: Install a new virtual server and install new software - would have to call Print Mail or Fiserv to help install | K13: Would recover in 511. | N13: None | P13: N/A | Q13: KBSC | R13: 511 | S13: Active Directory, MAIL, Fiserv Router, Fed Router, SCO, SC2, Director, Depcon, PMSYS01A, FSPS01 | T13: Confidential
B14: Decision Pro | E14: V | F14: 1 Day | G14: 2 Hours | J14: Restore image - call manufacturer for help if necessary | K14: Would recover in 511. | N14: Backup snapshot | P14: 1 Day - would have to go back to previous days' data. | Q14: KBSC | R14: 511 | T14: Confidential
B15: Dell iSensor (internal & external) | C15: SecureWorks IDS/IPS | E15: V | F15: 4 Hours | G15: 4 Hours | Q15: KBSC | S15: Fiber Line | T15: Private
B16: Director | C16: Director application and content management (SQL Database) stores scanned images. Called cold reporting | D16: MS Windows Server 2008R2 | E16: V | F16: 1 Day | G16: 6 Hours | J16: Create a new virtual server, restore from backup | K16: Would recover the server and application in 511. | N16: Backup snapshot | P16: 1 Day - would have to go back to previous days' data. | Q16: KBSC | R16: 511 | S16: Fiserv Router | T16: Confidential
B17: Director SQL | C17: Director application and content management (SQL Database) stores scanned images. Called cold reporting | D17: MS Windows Server 2008R2 | E17: V | F17: 1 Day | G17: 6 Hours | J17: Create a new virtual server, restore from backup | K17: Would recover the server and application in 511. | N17: Backup snapshot | P17: 1 Day - would have to go back to previous days' data. | Q17: KBSC | R17: 511 | S17: Fiserv Router | T17: Confidential
B18: DISKXTENDER
B19: DMZ | C19: Threat Management Gateway - DMZ software | D19: MS Windows Server 2008R2 | E19: V | F19: 4 Hours | G19: 4 Hours | J19: Deploy new virtual machine, reinstall software | K19: Exists in 511 Datacenter | Q19: 511 Datacenter | S19: Fiber Line | T19: Private
B20: DVR | C20: Video software for office cameras - 1 in each office | D20: ESM | E20: P | F20: 1 Day | G20: 10 Days + 2 Hours | J20: Order a new DVR (10 days) and install the cameras | K20: Order a new DVR (10 days) and install the cameras | Q20: All offices | R20: All offices | S20: MPLS, Routers, Firewall, Switches, Active Directory, Security, ISM | T20: Private
B21: EMC Clarioin SAN | C21: Storage | E21: V | F21: 4 Hours | G21: Failover | Q21: KBSC | R21: 511 | S21: Routers, Firewall | T21: N/A
B22: emc Recover Point | C22: 2 | E22: V | F22: 4 Hours | G22: Failover | Q22: KBSC | R22: 511 | S22: Routers, Firewall | T22: N/A
B23: eStatements | C23: Statement print server | D23: Microsoft Windows 7 | E23: V | F23: 4 Hours | G23: 4 Hours | N23: None | P23: N/A | Q23: KBSC | R23: 511 | S23: Routers, Firewall, Switches, Active Directory, Exchange, Fiserv Router, Fed Router, Director | T23: Confidential
B24: Exchange | C24: Email Servers | D24: Microsoft Exchange 2013 | E24: V | F24: 4 Hours | G24: 4 Hours | J24: Create a new virtual server and restore from backup - would run on the host in 511 | N24: Use the backup snapshot, rebuild and restore from backup. | P24: 1 Day - would have to go back to previous days' data. | Q24: KBSC | R24: 511 | S24: Routers, Firewall, Switches, Active Directory | T24: Confidential
B25: Expedite | C25: Platform BPM (Business Process Manager) Manager and Administrator | D25: MS Windows Server 2008R2 | E25: V | F25: 4 Hours | G25: 2 Hours | J25: Create a new virtual server, restore from backup | K25: Would recover the Fiserv server in 511. | N25: Backup snapshot | P25: 1 Day - would have to go back to previous days' data. | Q25: KBSC | R25: 511 | S25: Active Directory, and Fiserv Router | T25: Confidential
B26: ExpediteSQL
B27: Fed Advantage Router/Fedline VPN | C27: Cisco 1800 Series Router that goes to the Fed | E27: P | F27: 4 Hours | G27: 1 Hour | J27: For production would call the Fed and have it shipped immediataely and then install | K27: There is a duplicate Fed Router in 511. | Q27: KBSC | R27: 511 - extra router located here | S27: MPLS, Routers, Firewall, Switches | T27: N/A
B28: FirstData | C28: Cisco 1811 Router that goes to First Data for ATMS | E28: P | F28: 1 Day | G28: 2 Days | J28: Would call First Data and have it shipped immediately and then install | K28: Would install this in 511 | Q28: KBSC | R28: None in 511 - this is a single point of failure | S28: T-1 to Qwest | T28: N/A
B29: Fiserv | C29: Cisco 1841 Router that goes to Fiserv | F29: 4 Hours | G29: 2 Days | J29: Would call Fiserv and have it shipped immediately and then install | K29: Would install this in 511 | Q29: KBSC | S29: T-1 to Qwest | T29: N/A
B30: Host | C30: Multiple Host Servers for Virtual Environment (each host runs 12 virtual machines) | D30: MS Windows Server 2008R2 | E30: P | F30: 4 Hours | G30: 10 Days + 1 Day - never recovered | J30: 10 in the production site - if one fails, move all servers to live host | K30: 5 in the DR center | N30: None | P30: N/A | Q30: KBSC | R30: 511 | S30: Routers, Firewall, Switches | T30: N/A
B31: ICM
B32: Intuit
B33: ISM | C33: Badge proximity software server (security) | D33: Microsoft Windows 7 | E33: V | F33: 4 Hours | G33: 4 Hours - never recovered | J33: Restore image - call manufacturer for help if necessary | N33: Backup snapshot | P33: N/A | Q33: KBSC | R33: 511 | S33: MPLS, Routers, Firewall, Switches, Active Directory, Premise panels, Prox readers and anywhere usb device | T33: Private
B34: KBFS - File server | C34: Public Folders, User Folders, Team Folders (Unstructured data) | D34: MS Windows Server 2008R2 | E34: V | F34: 4 Hours | G34: 2 days | J34: Create a new virtual server, restore from backup, apply security | P34: 1 Day - would have to go back to previous days' data. | Q34: KBSC | R34: 511 | S34: Routers, Firewall, Switches, Active Directory | T34: Confidential
B35: KBINSIGHT
B36: KBSECURITY
B37: LaserPro
B38: Lockbox01 | C38: External lockbox web access | D38: MS Windows Server 2008R2 | E38: V | F38: 1 Day | G38: 1 Day | N38: Backup snapshot | Q38: KBSC | S38: Routers, Firewall, Switches, Active Directory | T38: Confidential
B39: Logrhythm
B40: Lync2013 | D40: Microsoft Lync 2013 | E40: V | F40: 4 Hours | G40: 4 Hours | N40: Interfaces with exchange keeps all of the messages (MAIL) | P40: 1 Day - would have to go back to previous days' data. | Q40: KBSC | R40: 511 | S40: Routers, Firewall, Switches, Active Directory, Exchange, iSensor, TMG | T40: Private
...

Sheet Application Matrix
E1: CLIENT SERVICES | J1: Credit | Z1: Deposit Operations | AL1: Fee Based | AT1: Finance and Accounting | AZ1: Human Resources, Marketing, Training - Branch Administration | BK1: Risk Management | BO1: Solutions | BP1: Solutions | BQ1: Solutions | BR1: Solutions | BS1: Technology | BZ1: Executive
D2: Business Process | E2: =('Process Matrix'!D3) -> Customer Service of Commercial Banking Products and Services | F2: =('Process Matrix'!D4) -> Account Open, Close Services | G2: =('Process Matrix'!D5) -> Account Transactions | H2: =('Process Matrix'!D6) -> ATM Services | I2: =('Process Matrix'!D7) -> Safe Deposit | J2: =('Process Matrix'!D8) -> Loan Underwriting, Approval | K2: =('Process Matrix'!D9) -> Collections | L2: =('Process Matrix'!D10) -> Loan Approval | M2: =('Process Matrix'!D11) -> ALLL Calculation (for Call Report) | N2: =('Process Matrix'!D12) -> Portfolio Monitoring | O2: =('Process Matrix'!D13) -> Underwriting, Approval | P2: =('Process Matrix'!D14) -> Appraisal, Evaluations | Q2: =('Process Matrix'!D15) -> Financial Monitoring | R2: =('Process Matrix'!D16) -> Loan Maintenance | S2: =('Process Matrix'!D17) -> Loan Closing | T2: =('Process Matrix'!D18) -> Underwriting and Disclosures | U2: =('Process Matrix'!D19) -> Loan Documentation | V2: =('Process Matrix'!D20) -> Loan Closing | W2: =('Process Matrix'!D21) -> Perfecting Collateral | X2: =('Process Matrix'!D22) -> Loan Documentation Preparation | Y2: =('Process Matrix'!D23) -> Loan Documentation Processing | Z2: =('Process Matrix'!D24) -> Account Maintenance | AA2: =('Process Matrix'!D25) -> Levies, Garnishments | AB2: =('Process Matrix'!D26) -> ACH File and Funds Transfer Processing & Returns | AC2: =('Process Matrix'!D27) -> Online Banking Maintenance & Support | AD2: =('Process Matrix'!D28) -> Large Item Returns | AE2: =('Process Matrix'!D29) -> Daily processing of non-posts, chargeback's & return decision items | AF2: =('Process Matrix'!D30) -> Wire Processing | AG2: =('Process Matrix'!D31) -> Correspondent Daily Settlement | AH2: =('Process Matrix'!D32) -> Lockbox Payment | AI2: =('Process Matrix'!D33) -> Deposit Verifications | AJ2: =('Process Matrix'!D34) -> Misc. Research Requests, IRS Tax reporting, Unclaimed property | AK2: =('Process Matrix'!D35) -> OFAC validation | AL2: =('Process Matrix'!D36) -> Sales of Merchant Credit Card Processing | AM2: =('Process Matrix'!D37) -> Sales of Business Credit Cards | AN2: =('Process Matrix'!D38) -> Training of Commercial Banking Products and Services | AO2: =('Process Matrix'!D39) -> Sell Services | AP2: =('Process Matrix'!D40) -> Sell Services | AQ2: =('Process Matrix'!D41) -> Loan Processing | AR2: =('Process Matrix'!D42) -> Loan Application Delivery | AS2: =('Process Matrix'!D43) -> Participation, Serviced Loan Management | AT2: =('Process Matrix'!D44) -> Accounts Payable | AU2: =('Process Matrix'!D45) -> Accounts Reconciliation | AV2: =('Process Matrix'!D46) -> Payroll | AW2: =('Process Matrix'!D47) -> Payments, Advances, Loan Non-posts | AX2: =('Process Matrix'!D48) -> Financial Reporting | AY2: =('Process Matrix'!D49) -> Cash & Liquidity Management | AZ2: =('Process Matrix'!D50) -> Desktop Hardware & Application Support | BA2: =('Process Matrix'!D51) -> Ticket Requests | BB2: =('Process Matrix'!D52) -> Branch Support | BC2: =('Process Matrix'!D53) -> Bank Communications | BD2: =('Process Matrix'!D54) -> Process & Procedures | BE2: =('Process Matrix'!D55) -> Talent Acquisition | BF2: =('Process Matrix'!D56) -> Benefit Administration | BG2: =('Process Matrix'!D57) -> Staffing Management | BH2: =('Process Matrix'!D58) -> Marketing of Commercial Banking Products and Services | BI2: =('Process Matrix'!D59) -> Create Advertising, Promotions | BJ2: =('Process Matrix'!D60) -> Compliance Training | BK2: =('Process Matrix'!D61) -> Internal Audit | BL2: =('Process Matrix'!D62) -> Annual Planning: Risk Assessments, Plans, Priorities | BM2: =('Process Matrix'!D63) -> Implement new and changes to regulations and monitor progress, performance | BN2: =('Process Matrix'!D64) -> Staff Resource for Compliance Issues | BO2: =('Process Matrix'!D65) -> Client software support | BP2: =('Process Matrix'!D66) -> ATM/Debit Card Services | BQ2: =('Process Matrix'!D67) -> Sales of Banking Products and Services | BR2: =('Process Matrix'!D68) -> Client account support | BS2: =('Process Matrix'!D69) -> Branch Capture, Merchant Capture & Daily Letter Processing and Balancing | BT2: =('Process Matrix'!D70) -> Statement/Notice production | BU2: =('Process Matrix'!D71) -> 0 | BV2: =('Process Matrix'!D72) -> 0 | BW2: =('Process Matrix'!D73) -> 0 | BX2: =('Process Matrix'!D74) -> 0 | BY2: =('Process Matrix'!D75) -> 0 | BZ2: =('Process Matrix'!D76) -> 0 | CA2: =('Process Matrix'!D77) -> 0 | CB2: =('Process Matrix'!D78) -> 0 | CC2: =('Process Matrix'!D79) -> 0 | CD2: =('Process Matrix'!D80) -> 0
D3: RTO (In Days) | E3: 30 DAYS | F3: 6 HOURS | G3: 1 DAY | H3: 1 DAY | I3: 1 DAY | K3: 1 DAY | L3: 1 DAY | M3: 1 DAY | N3: 1 DAY | O3: 30 DAYS | P3: 30 DAYS | Q3: 30 DAYS | R3: 30 DAYS | S3: 30 DAYS | T3: 3 DAYS | U3: 3 DAYS | V3: 30 DAYS | W3: 6 HOURS | X3: 1 DAY | Y3: 3 DAYS | Z3: 30 DAYS | AA3: 30 DAYS | AB3: 1 DAY | AC3: 1 DAY | AD3: 4 HOURS | AE3: 4 HOURS | AF3: 30 DAYS | AG3: 31 | AH3: 30 DAYS | AI3: 1 DAY | AJ3: 5 DAYS | AK3: 10 DAYS | AL3: 3 DAYS | AM3: 10 DAYS | AN3: 3 DAYS | AO3: 30 DAYS | AP3: 10 DAYS | AQ3: 30 DAYS | AR3: 30 DAYS | AS3: 30 DAYS | AT3: 30 DAYS | AU3: 2 DAYS | AV3: 3 DAYS | AW3: 14 DAYS | AX3: 14 DAYS | AY3: 90 DAYS | AZ3: 90 DAYS | BA3: 90 DAYS | BB3: 90 DAYS | BC3: 90 DAYS | BD3: 91 DAYS | BE3: 30 DAYS | BF3: 3 DAYS | BG3: 14 DAYS | BH3: 14 DAYS | BI3: 90 DAYS | BJ3: 90 DAYS | BK3: 90 DAYS | BL3: 90 DAYS | BM3: 90 DAYS | BN3: 90 DAYS | BO3: 91 DAYS | BP3: 30 DAYS | BQ3: 30 DAYS | BR3: 3 DAYS | BS3: 14 DAYS | BT3: 14 DAYS | BU3: 14 DAYS | BV3: 90 DAYS | BW3: 90 DAYS | BX3: 90 DAYS | BY3: 90 DAYS | BZ3: 90 DAYS | CA3: 91 DAYS | CB3: 30 DAYS | CC3: 31 DAYS | CD3: 32 DAYS
D4: RPO (In Days)
A5: Application | B5: Service Type | C5: Data Confidentiality Categorization ↓ | D5: App RTO ↓ (in days)
A6: 360 View
A7: ABG | B7: Website Only
A8: Access Manager
A9: Adobe | B9: In-house | C9: C | D9: =MIN(E9:BC9) -> 0.16 | E9: 30 | F9: 0.25 | G9: 1 | H9: 1 | I9: 1 | K9: 1 | L9: 1 | M9: 1 | N9: 1 | O9: 30 | P9: 30 | Q9: 30 | T9: 3 | U9: 3 | V9: 30 | W9: 0.25 | X9: 1 | Y9: 3 | Z9: 30 | AA9: 30 | AB9: 1 | AC9: 1 | AD9: 0.16 | AE9: 0.16 | AF9: 30 | AG9: 30 | AH9: 30 | AI9: 1 | AJ9: 5 | AK9: 10 | AL9: 3 | AM9: 10 | AN9: 3 | AO9: 30 | AP9: 10 | AQ9: 30 | AR9: 30 | AS9: 30 | AT9: 30 | AY9: 90 | AZ9: 90 | BA9: 90 | BB9: 90 | BC9: 90 | BD9: 90 | BE9: 30 | BI9: 90 | BJ9: 90 | BK9: 90 | BL9: 90 | BM9: 90 | BN9: 90 | BO9: 90 | BP9: 30 | BQ9: 30 | BV9: 90 | BW9: 90 | BX9: 90 | BY9: 90 | BZ9: 90 | CA9: 90 | CB9: 30 | CC9: 30 | CD9: 30
A10: ADP Workforce | B10: SaaS | C10: C
A11: Andera -Bottomline
A12: C3 - Fiserv Support
A13: C3 Financial
A14: Call Reporter Software (Y9?) | C14: PR | D14: =MIN(E14:BC14) -> 3 | AV14: 3 | BF14: 3 | BR14: 3
A15: Card Logics
A16: CashWare - recycler integration
A17: Centrix (ACH/TMS/ARS management)
A18: CheckPoint (FW)
A19: ClickSwitch
A20: Company Website - KB.com
A21: Compass
A22: CrediQuest
A23: CRIF
A24: CST - Consumer Bill Pay
A25: DecisionPro
A26: Deluxe Checks
... A28: Digital Insight
A29: Director | B29: In-house | C29: C | D29: =MIN(E29:BC29) -> 1 | K29: 1 | L29: 1 | M29: 1 | N29: 1 | T29: 3 | U29: 3 | Y29: 3 | AA29: 30 | AG29: 30 | AJ29: 5 | AK29: 10 | AL29: 3 | AM29: 10 | AU29: 2 | AV29: 3 | AW29: 14 | AY29: 90 | BA29: 90 | BB29: 90 | BC29: 90 | BD29: 90 | BF29: 3 | BG29: 14 | BI29: 90 | BK29: 90 | BL29: 90 | BM29: 90 | BN29: 90 | BO29: 90 | BR29: 3 | BS29: 14 | BV29: 90 | BX29: 90 | BY29: 90 | BZ29: 90 | CA29: 90
A30: eCorp (Fiserv)
A31: ECOS Gift Card | B31: Website Only
A32: Elan | B32: Website Only
A33: Elan - Elavon | B33: Website Only
A34: Elan - OnDot | B34: Website Only
A35: E-Mail/Outlook | B35: In-house | C35: C | D35: =MIN(E35:BC35) -> 0.16 | E35: 30 | F35: 0.25 | G35: 1 | H35: 1 | I35: 1 | K35: 1 | L35: 1 | M35: 1 | N35: 1 | O35: 30 | P35: 30 | Q35: 30 | R35: 30 | S35: 30 | T35: 3 | U35: 3 | V35: 30 | W35: 0.25 | X35: 1 | Y35: 3 | Z35: 30 | AA35: 30 | AB35: 1 | AC35: 1 | AD35: 0.16 | AE35: 0.16 | AF35: 30 | AG35: 30 | AH35: 30 | AI35: 1 | AJ35: 5 | AK35: 10 | AL35: 3 | AM35: 10 | AN35: 3 | AO35: 30 | AP35: 10 | AQ35: 30 | AR35: 30 | AS35: 30 | AT35: 30 | AU35: 2 | AV35: 3 | AW35: 14 | AX35: 14 | AY35: 90 | AZ35: 90 | BA35: 90 | BB35: 90 | BC35: 90 | BD35: 90 | BE35: 30 | BF35: 3 | BG35: 14 | BH35: 14 | BI35: 90 | BJ35: 90 | BK35: 90 | BL35: 90 | BM35: 90 | BN35: 90 | BO35: 90 | BP35: 30 | BQ35: 30 | BR35: 3 | BS35: 14 | BT35: 14 | BU35: 14 | BV35: 90 | BW35: 90 | BX35: 90 | BY35: 90 | BZ35: 90 | CA35: 90 | CB35: 30 | CC35: 30 | CD35: 30
A36: Ensenta - mobile deposits
A37: Equifax/ePort | C37: C | D37: =MIN(E37:BC37) -> 3 | T37: 3 | U37: 3 | AF37: 30 | AK37: 10 | AM37: 10 | AP37: 10 | AY37: 90 | BA37: 90 | BB37: 90 | BC37: 90 | BD37: 90 | BI37: 90 | BK37: 90 | BL37: 90 | BM37: 90 | BN37: 90 | BO37: 90 | BV37: 90 | BX37: 90 | BY37: 90 | BZ37: 90 | CA37: 90
A38: Exact TMS - Positive Pay
A39: Express Gift Card | B39: Website Only
A40: FedLine & Fed Advantage | C40: C | D40: =MIN(E40:BC40) -> 30 | AA40: 30
A41: Finance Works
...

Sheet Process Matrix
A1: Process Information | I1: Recovery Requirements | M1: Customer / Dependencies | Q1: Intangible Impact (H, M, L, None) | Y1: Financial Impact | AD1: Manual Workaround | AG1: Applications Needed for Process | DQ1: Cross-Training | DW1: Alternate Locations | EB1: Vendor Reliance | ED1: Process Resources
A2: Plan Process Owner | B2: Parent Department | C2: Business Unit | D2: Business Process | E2: Process Description | F2: Process Frequency | G2: Location | H2: High Impact Times | I2: Requested RTO | J2: RTO (Final Approved) | K2: Requested RPO | L2: RTO / RPO Justification | M2: Internal Customer | N2: External Customer | O2: What BU relies on this process? | P2: What BU do you depend on to perform this process? | Q2: Customer Service | R2: Company Image | S2: Regulatory /Contractual | T2: Vendor Relations | U2: Competitive Advantage | V2: Accuracy | W2: Productivity | X2: Explanation | Y2: Lost Revenue | Z2: Deferred Revenue | AA2: Fines / Penalties /Lawsuits | AB2: Other Costs | AC2: Explanation of Financial Impacts | AD2: Is there a Work-Around | AE2: Maximum Delay of Process (MTD) | AF2: Describe | AG2: ='Application Matrix'!A6 -> 360 View | AH2: ='Application Matrix'!A7 -> ABG | AI2: ='Application Matrix'!A8 -> Access Manager | AJ2: ='Application Matrix'!A9 -> Adobe | AK2: ='Application Matrix'!A10 -> ADP Workforce | AL2: ='Application Matrix'!A11 -> Andera -Bottomline | AM2: ='Application Matrix'!A12 -> C3 - Fiserv Support | AN2: ='Application Matrix'!A13 -> C3 Financial | AO2: ='Application Matrix'!A14 -> Call Reporter Software (Y9?) | AP2: ='Application Matrix'!A15 -> Card Logics | AQ2: ='Application Matrix'!A16 -> CashWare - recycler integration | AR2: ='Application Matrix'!A17 -> Centrix (ACH/TMS/ARS management) | AS2: ='Application Matrix'!A18 -> CheckPoint (FW) | AT2: ='Application Matrix'!A19 -> ClickSwitch | AU2: ='Application Matrix'!A20 -> Company Website - KB.com | AV2: ='Application Matrix'!A21 -> Compass | AW2: ='Application Matrix'!A22 -> CrediQuest | AX2: ='Application Matrix'!A23 -> CRIF | AY2: ='Application Matrix'!A24 -> CST - Consumer Bill Pay | AZ2: ='Application Matrix'!A25 -> DecisionPro | BA2: ='Application Matrix'!A26 -> Deluxe Checks | BB2: ='Application Matrix'!A27 -> Deposit Pro | BC2: ='Application Matrix'!A28 -> Digital Insight | BD2: ='Application Matrix'!A29 -> Director | BE2: ='Application Matrix'!A30 -> eCorp (Fiserv) | BF2: ='Application Matrix'!A31 -> ECOS Gift Card | BG2: ='Application Matrix'!A32 -> Elan | BH2: ='Application Matrix'!A33 -> Elan - Elavon | BI2: ='Application Matrix'!A34 -> Elan - OnDot | BJ2: ='Application Matrix'!A35 -> E-Mail/Outlook | BK2: ='Application Matrix'!A36 -> Ensenta - mobile deposits | BL2: ='Application Matrix'!A37 -> Equifax/ePort | BM2: ='Application Matrix'!A38 -> Exact TMS - Positive Pay | BN2: ='Application Matrix'!A39 -> Express Gift Card | BO2: ='Application Matrix'!A40 -> FedLine & Fed Advantage | BP2: ='Application Matrix'!A41 -> Finance Works | BQ2: ='Application Matrix'!A42 -> FMSI - scheduling | BR2: ='Application Matrix'!A43 -> FraudMap (GA) for wires, ACH, BOLB | BS2: ='Application Matrix'!A44 -> FRB Axway Secure Client | BT2: ='Application Matrix'!A45 -> FTP | BU2: ='Application Matrix'!A46 -> GoToAssist | BV2: ='Application Matrix'!A47 -> GoToMeeting | BW2: ='Application Matrix'!A48 -> GoToTraining | BX2: ='Application Matrix'!A49 -> Greenview | BY2: ='Application Matrix'!A50 -> HSA Service center | BZ2: ='Application Matrix'!A51 -> Ignite | CA2: ='Application Matrix'!A52 -> intranet | CB2: ='Application Matrix'!A53 -> Integrated Teller | CC2: ='Application Matrix'!A54 -> Internet | CD2: ='Application Matrix'!A55 -> IRA Service center | CE2: ='Application Matrix'!A56 -> IVR Messaging | CF2: ='Application Matrix'!A57 -> external hotline | CG2: ='Application Matrix'!A58 -> LaserPro | CH2: ='Application Matrix'!A59 -> Live Person | CI2: ='Application Matrix'!A60 -> MasterCard Applepay | CJ2: ='Application Matrix'!A61 -> Milliman Benefits | CK2: ='Application Matrix'!A62 -> Mobile Iron | CL2: ='Application Matrix'!A63 -> MPC Architect | CM2: ='Application Matrix'!A64 -> MS Office | CN2: ='Application Matrix'!A65 -> Navigator Core (Fiserv) | CO2: ='Application Matrix'!A66 -> NetEconomy | CP2: ='Application Matrix'!A67 -> Oaisys | CQ2: ='Application Matrix'!A68 -> ORCC (Fiserv) | CR2: ='Application Matrix'!A69 -> Penley (FIS/Qualfile) | CS2: ='Application Matrix'!A70 -> Phone | CT2: ='Application Matrix'!A71 -> PhoneFactor | CU2: ='Application Matrix'!A72 -> Platform/BPM/Expedite (Acct Opening) | CV2: ='Application Matrix'!A73 -> PrairieFyre | CW2: ='Application Matrix'!A74 -> Preferred One | CX2: ='Application Matrix'!A75 -> Print Services | CY2: ='Application Matrix'!A76 -> Public Folders (shared drives) | CZ2: ='Application Matrix'!A77 -> Quickbooks/Quicken | DA2: ='Application Matrix'!A78 -> RPX | DB2: ='Application Matrix'!A79 -> SecureWorks Portal | DC2: ='Application Matrix'!A80 -> Source Capture (SCO)/Merchant Capture | DD2: ='Application Matrix'!A81 -> Survey Gizmo | DE2: ='Application Matrix'!A82 -> Voicemail | DF2: ='Application Matrix'!A83 -> Web Capture | DG2: ='Application Matrix'!A84 -> Websense | DH2: ='Application Matrix'!A85 -> Wells Fargo Wires | DI2: ='Application Matrix'!A86 -> Wire Xchange | DJ2: ='Application Matrix'!A87 -> Zix | DK2: ='Application Matrix'!A88 -> Arta & Hostbridge | DL2: ='Application Matrix'!A89 -> BancWare | DM2: ='Application Matrix'!A108 -> Remote Admin (Radmin) | DN2: ='Application Matrix'!A118 -> Wolters Kluwer | DO2: Any apps w/ RTO different than process? | DP2: Classification? | DQ2: # of staff to perform process | DR2: Min # of staff needed | DS2: Work in shifts? | DT2: Number of other staff cross-trained within BU | DU2: Other BU or staff that can perform process | DV2: External vendor that can perform process | DW2: Remotely | DX2: Other Work Location | DY2: Home | DZ2: If yes, Have you performed remotely? | EA2: Can process be performed off-hrs? | EB2: Who are your critical vendors? | EC2: Have you identified alternate vendors? | ED2: Special Forms Needed | EE2: Vital Records Needed | EF2: Published Phone Numbers to be Restored | EG2: Special Equipment Needed | EH2: Special Websites Needed (not associated with applications)
B3: Business Banking | C3: Business Banking | D3: Customer Service of Commercial Banking Products and Services | E3: Provide customer service of Commercial Deposit Accounts, Cash Management products and services. | F3: DAILY | G3: ALL 20 | I3: 30 DAYS | J3: 30 DAYS | K3: 30 DAYS | L3: Could do this process manually or it could wait | N3: X | Q3: H | R3: H | S3: N | T3: N | U3: H | V3: N | W3: H | X3: This could be done manually | Y3: H | Z3: H | AA3: N | AB3: L | AD3: YES | AF3: Manual Process | AG3: X | AH3: X | AI3: X | AJ3: X | AL3: X | AM3: X | AN3: X | AO3: X | BO3: X | BZ3: X | CN3: X | CY3: X | DN3: X | DP3: PU | DW3: YES | DX3: YES | DY3: YES | DZ3: YES | EA3: YES
B4: Consumer Banking | C4: Branches | D4: Account Open, Close Services | E4: Open/closing savings, checking, money market, certificates and stop payments. | F4: WEEKLY | G4: ALL 20 | I4: 3 DAYS | J4: 3 DAYS | K4: 4 HRS | L4: Could do this process manually for a few days | N4: X | Q4: H | R4: H | S4: L | T4: L | U4: H | V4: H | W4: H | X4: High customer and revenue impact | Y4: H | Z4: M | AA4: N | AB4: M | AC4: Need money in deposit accounts to lend | AD4: YES | AE4: 3 DAYS | AF4: Could type the documents | AG4: X | AH4: X | AI4: X | AJ4: X | AL4: X | AM4: X | AN4: X | AO4: X | AP4: X | AR4: X | AT4: X | AU4: X | BB4: X | BD4: X | BG4: X | BJ4: X | BO4: X | BZ4: X | CC4: X | CN4: X | CY4: X | DB4: X | DN4: X | DP4: C | DW4: NO | DX4: YES | DY4: NO | DZ4: NO | EA4: NO | EB4: Fiserv, Deluxe | EC4: NO | EG4: Typewriter and an encoder
B5: Consumer Banking | C5: Branches | D5: Account Transactions | E5: Process withdrawals, deposits, loan payments, dispense cash, cashier checks | F5: DAILY | G5: ALL 20 | I5: 3 DAYS | J5: 3 DAYS | K5: 4 HRS | L5: Could do this process manually for a few days | M5: X | N5: X | O5: Branches | P5: Deposit Operations | Q5: H | R5: H | S5: M | T5: L | U5: H | V5: H | W5: H | X5: High customer impact | Y5: M | Z5: M | AA5: H | AB5: H | AD5: YES | AE5: 3 DAYS | AF5: Hand written transactions | AG5: X | AI5: X | AJ5: X | AL5: X | AM5: X | AN5: X | AO5: X | AT5: X | BB5: X | BJ5: X | BL5: X | BO5: X | BW5: X | BZ5: X | CC5: X | CE5: X | CK5: X | CN5: X | CV5: X | CY5: X | DB5: X | DD5: X | DN5: X | DP5: C | DW5: NO | DX5: YES | DY5: NO | DZ5: NO | EA5: NO | EB5: Fiserv | EC5: NO | ED5: Deposit Slips, Counter Checks, and Withdrawal Slips, Cashier Check Stock, Gift Card Stock | EG5: Encoder, Chex Printer and Ink
B6: Consumer Banking | C6: Branches | D6: ATM Services | E6: Filling and Balancing ATM Machine | F6: DAILY | G6: ALL 20 | I6: 30 DAYS | J6: 30 DAYS | K6: 30 DAYS | L6: This could wait | N6: X | Q6: M | R6: M | S6: M | T6: L | U6: L | V6: H | W6: H | X6: This could wait for a few days | Y6: L | Z6: L | AA6: M | AB6: M | AD6: NO | AF6: Not critical | AG6: X | AI6: X | AJ6: X | AL6: X | AM6: X | AN6: X | AO6: X | AT6: X | AY6: X | BB6: X | BO6: X | BZ6: X | CN6: X | CY6: X | DN6: X | DP6: PR & C | DW6: NO | DX6: NO | DY6: NO | DZ6: NO | EA6: YES | EB6: Loomis, SPC, Rochester Armoured, Granite City | EC6: Pendum, Dunbar, NuSource | EE6: Stat Key through First Data for remote balancing
B7: Consumer Banking | C7: Branches | D7: Safe Deposit | E7: Sale of an access to Safe Deposit boxes. | F7: WEEKLY | G7: ALL 20 | I7: 30 DAYS | J7: 30 DAYS | K7: 30 DAYS | L7: This is a manual process | N7: X | Q7: M | R7: H | S7: L | T7: L | U7: M | V7: H | W7: L | X7: This is a manual process and could still be done | Y7: L | Z7: L | AA7: L | AB7: L | AD7: YES | AE7: 30 DAYS | AF7: This is a manual process | AG7: X | AH7: X | AL7: X | AM7: X | AN7: X | AO7: X | DP7: C | DW7: NO | DX7: YES | DY7: NO | DZ7: NO | EA7: NO | EB7: Security Products | EC7: NO
B8: Credit | C8: Credit | D8: Loan Underwriting, Approval | E8: Prepare loan presentation, evaluation and underwriting documents. | F8: DAILY | G8: ALL 20 | I8: 10 DAYS | J8: 10 DAYS | K8: 15 DAYS | L8: Could do the presentation verbally | N8: X | Q8: H | R8: H | S8: L | T8: L | U8: H | V8: H | W8: H | X8: High customer impact | Y8: M | Z8: M | AA8: L | AB8: L | AD8: YES | AE8: 10 DAYS | AF8: Could verbally do the presentation | AG8: X | AI8: X | AJ8: X | AL8: X | AM8: X | AN8: X | AO8: X | AT8: X | AU8: X | BB8: X | BC8: X | BG8: X | BO8: X | BZ8: X | CN8: X | CY8: X | DN8: X | DP8: C | DW8: YES | DX8: YES | DY8: YES | DZ8: YES | EA8: YES | EB8: Fiserv | EC8: NO
B9: Credit | C9: Credit | D9: Collections | F9: WEEKLY | G9: KBSC | I9: 10 DAYS | J9: 10 DAYS | K9: 15 DAYS | M9: X | N9: X | Q9: H | R9: H | S9: L | T9: L | U9: H | V9: H | W9: H | X9: High customer impact | Y9: M | Z9: M | AA9: L | AB9: L | AD9: YES | AE9: 10 DAYS | AG9: X | AI9: X | AJ9: X | AL9: X | AM9: X | AN9: X | AO9: X | AT9: X | AU9: X | BB9: X | BC9: X | BG9: X | BO9: X | BZ9: X | CN9: X | CY9: X | DN9: X | DP9: C | DW9: YES | DX9: YES | DY9: YES | DZ9: NO | EA9: YES
B10: Credit | C10: Credit | D10: Loan Approval | E10: Seeking final approval from the various areas based on the dollar amount to grant the customer a loan. | F10: WEEKLY | G10: KBSC | I10: 30 DAYS | J10: 30 DAYS | K10: 4 HRS | L10: Meet in person | M10: X | O10: Business Banking | Q10: H | R10: H | S10: H | T10: N | U10: H | V10: H | W10: H | X10: High customer and revenue impact | Y10: H | Z10: H | AA10: N | AB10: N | AD10: YES | AE10: 30 DAYS | AF10: Physically meet with approvers | AI10: X | AJ10: X | AL10: X | AM10: X | AN10: X | AO10: X | BO10: X | BZ10: X | CN10: X | CY10: X | DN10: X | DP10: C | DW10: YES | DX10: YES | DY10: YES | DZ10: NO | EA10: YES
B11: Credit | C11: Credit | D11: ALLL Calculation (for Call Report) | E11: Quarterly analysis of the appropriate mount of ALLL, including review of Criticized Asset Reports, Risk Ratings, Impairment Calculations, Classified Loans | F11: MONTHLY | G11: KBSC | I11: 1 DAY | J11: 1 DAY | K11: 4 HRS | L11: If timing was critical could ask for an extension | N11: X | Q11: H | R11: H | S11: H | T11: N | U11: M | V11: H | W11: H | X11: High customer impact | Y11: N | Z11: N | AA11: H | AB11: L | AD11: YES | AE11: 1 DAY | AF11: Could call and ask for an extension | AG11: X | AI11: X | AJ11: X | AL11: X | AM11: X | AN11: X | AO11: X | BB11: X | BI11: X | BO11: X | BV11: X | BZ11: X | CN11: X | CU11: X | CY11: X | DN11: X | DP11: C | DW11: YES | DX11: YES | DY11: YES | DZ11: NO | EA11: YES | EB11: Fiserv, SNL Banker | EC11: NO
B12: Credit | C12: Credit | D12: Portfolio Monitoring | E12: Monitor overdrafts, past dues, and BBC compliance to identify customer issues | F12: DAILY | G12: KBSC | I12: 5 DAYS | J12: 5 DAYS | K12: 1 DAY | L12: Could wait for 5 days | N12: X | Q12: L | R12: L | S12: M | T12: N | U12: L | V12: H | W12: M | X12: This could wait for a few days | Y12: N | Z12: N | AA12: L | AB12: L | AD12: NO | AE12: 5 DAYS | AF12: Could wait for a few days | AG12: X | AI12: X | AJ12: X | AL12: X | AM12: X | AN12: X | AO12: X | AT12: X | BB12: X | BI12: X | BO12: X | BV12: X | BZ12: X | CN12: X | CU12: X | CY12: X | DN12: X | DP12: C | DW12: YES | DX12: YES | DY12: YES | DZ12: NO | EA12: YES | EB12: Fiserv | EC12: NO
B13: Credit | C13: Credit | D13: Underwriting, Approval | E13: Prepare loan presentations for current and prospective customers; submit to SRLC for approval (Above $400K) | F13: DAILY | G13: KBSC | I13: 30 DAYS | J13: 30 DAYS | K13: 2 DAYS | L13: Could perform manually | M13: X | O13: Business Banking | Q13: H | R13: H | S13: M | T13: N | U13: H | V13: H | W13: H | X13: High customer impact | Y13: H | Z13: N | AA13: L | AB13: L | AD13: YES | AE13: 30 DAYS | AF13: Could do this long-hand if necessary and enter the information later | AG13: X | AI13: X | AJ13: X | AL13: X | AM13: X | AN13: X | AO13: X | AU13: X | BB13: X | BC13: X | BG13: X | BI13: X | BO13: X | BV13: X | BZ13: X | CN13: X | CU13: X | CY13: X | DN13: X | DP13: C | DW13: YES | DX13: YES | DY13: YES | DZ13: YES | EA13: YES | EB13: Fiserv | EC13: NO
B14: Credit | C14: Credit | D14: Appraisal, Evaluations | E14: Order all commercial and residential appraisals; work with appraisers, appraisal reviewer and ARC designee to finalize and approve; prepare RE evaluations and work with ARC designee for Approval | F14: DAILY | G14: KBSC | I14: 30 DAYS | J14: 30 DAYS | K14: 2 DAYS | L14: Could perform manually | M14: X | O14: Business Banking | Q14: H | R14: H | S14: H | T14: H | U14: H | V14: H | W14: H | X14: High customer impact | Y14: H | Z14: N | AA14: L | AB14: L | AD14: YES | AE14: 30 DAYS | AF14: Could do this long-hand if necessary and enter the information later | AG14: X | AI14: X | AJ14: X | AK14: X | AL14: X | AM14: X | AN14: X | AO14: X | AT14: X | BB14: X | BO14: X | BZ14: X | CN14: X | CY14: X | DN14: X | DP14: C | DW14: YES | DX14: YES | DY14: YES | DZ14: YES | EA14: YES | EB14: Fiserv, Appraisers
B15: Credit | C15: Credit | D15: Financial Monitoring | E15: Regular monitoring of existing customers financial performance by spreading financial statements, updating trend cards, monthly marketable securities report. | F15: DAILY | G15: KBSC | I15: 30 DAYS | J15: 30 DAYS | K15: 2 DAYS | L15: Could perform manually | M15: X | O15: Business Banking | Q15: M | R15: H | S15: M | T15: N | U15: M | V15: H | W15: H | X15: High customer impact | Y15: L | Z15: N | AA15: L | AB15: L | AD15: YES | AE15: 30 DAYS | AF15: Could do this long-hand if necessary and enter the information later | AG15: X | AI15: X | AJ15: X | AL15: X | AN15: X | AO15: X | BB15: X | BO15: X | BZ15: X | CN15: X | CY15: X | DN15: X | DP15: C | DW15: YES | DX15: YES | DY15: YES | DZ15: YES | EA15: YES | EB15: Fiserv | EC15: NO
B16: Credit | C16: Loan Servicing | D16: Loan Maintenance | E16: Assist with updating file, address changes, and loan payments | F16: DAILY | G16: KBSC | I16: 3 DAYS | K16: 1 DAY | L16: This could be done manually | N16: X | Q16: H | R16: H | S16: L | T16: L | U16: H | V16: H | W16: H | X16: High customer impact | Y16: M | Z16: M | AA16: L | AB16: L | AD16: YES | AE16: 3 DAYS | AF16: Manually write up changes and input later | AG16: X | AI16: X | AJ16: X | AL16: X | AM16: X | AN16: X | AO16: X | AT16: X | BB16: X | BO16: X | BZ16: X | CN16: X | CY16: X | DN16: X | DP16: C | DW16: YES | DX16: YES | DY16: YES | DZ16: NO | EA16: NO | EB16: Fiserv and Wolters Kluwer | EC16: NO
B17: Credit | C17: Loan Servicing | D17: Loan Closing | E17: Coordinating the execution of the documents with customers and the Bank. | F17: DAILY | G17: KBSC | I17: 3 DAYS | J17: 3 DAYS | K17: 1 DAY | L17: Could do this manually for a while | N17: X | Q17: H | R17: H | S17: L | T17: L | U17: H | V17: H | W17: H | X17: High customer impact | Y17: M | Z17: M | AA17: L | AB17: L | AD17: YES | AE17: 3 DAYS | AF17: Could type the documents | AG17: X | AI17: X | AJ17: X | AL17: X | AM17: X | AN17: X | AO17: X | BB17: X | BO17: X | BZ17: X | CN17: X | CY17: X | DN17: X | DP17: C | DW17: YES | DX17: YES | DY17: YES | DZ17: YES | EA17: YES | EB17: Title Companies and Attorneys | EC17: NO
B18: Credit | C18: Loan Servicing | D18: Underwriting and Disclosures | E18: Pulling credit reports, flood certs and title work and reviewing. Pulling collateral evaluations and establishing insurance. Requesting early disclosures from our loan operations department. | F18: WEEKLY | G18: KBSC | I18: 10 DAYS | J18: 10 DAYS | K18: 4 HRS | L18: Could call or use the mail | M18: X | Q18: H | R18: H | S18: H | T18: H | U18: H | V18: H | W18: H | X18: High customer and revenue impact | Y18: H | Z18: H | AA18: H | AB18: H | AC18: Oreo, Impounding | AD18: YES | AE18: 2-4 Weeks | AF18: Call vendors, mail info, etc. | AG18: X | AH18: X | AI18: X | AJ18: X | AL18: X | AM18: X | AN18: X | AO18: X | AU18: X | BB18: X | BO18: X | BZ18: X | CN18: X | CY18: X | DN18: X | DP18: C | DW18: YES | DX18: YES | DY18: YES | DZ18: YES | EA18: YES | EB18: Equifax, Wolters Kluwer, approved title companies and approved appraisers | EC18: Yes list of approved vendors
B19: Credit | C19: Loan Servicing | D19: Loan Documentation | E19: After loan approval need to request loan documents from Loan Operations for checks and balances. | F19: WEEKLY | G19: KBSC | I19: 30 DAYS | J19: 30 DAYS | K19: 4 HRS | L19: Could work through this with an outside source | M19: X | Q19: H | R19: H | S19: H | T19: L | U19: H | V19: H | W19: H | X19: High customer and revenue impact | Y19: H | Z19: H | AA19: M | AB19: L | AD19: YES | AE19: 30 DAYS | AF19: Outside source, print a template | AG19: X | AI19: X | AJ19: X | AL19: X | AM19: X | AN19: X | AO19: X | BB19: X | BO19: X | BZ19: X | CN19: X | CY19: X | DN19: X | DP19: C | DW19: YES | DX19: YES | DY19: YES | DZ19: YES | EA19: YES | EE19: Consumer and Commercial Loan Worksheet
B20: Credit | C20: Loan Servicing | D20: Loan Closing | E20: Physical time with the client to sign the documents and close the loan. This also includes loan disbursement. | F20: WEEKLY | G20: KBSC | I20: 30 DAYS | J20: 30 DAYS | K20: 4 HRS | L20: Could work through this with an outside source | N20: X | Q20: H | R20: H | S20: H | T20: N | U20: H | V20: H | W20: H | X20: High customer and revenue impact | Y20: H | Z20: H | AA20: L | AB20: L | AD20: YES | AE20: 30 DAYS | AF20: Title company or close outside | AI20: X | AJ20: X | AL20: X | AM20: X | AN20: X | AO20: X | BB20: X | BO20: X | BZ20: X | CN20: X | CY20: X | DN20: X | DP20: C | DW20: YES | DX20: YES | DY20: YES | DZ20: YES | EA20: YES | EB20: Title Companies | EC20: List of specified title companies
B21: Credit | C21: Loan Servicing | D21: Perfecting Collateral | E21: Provide signed documentation to file the title of a vehicle, filing a mortgage, perfecting the lien, etc. to Loan Operations. | F21: WEEKLY | G21: KBSC | I21: 30 DAYS | J21: 30 DAYS | K21: 2 WEEKS | L21: Personally deliver documents | N21: X | Q21: H | R21: H | S21: H | T21: H | U21: H | V21: H | W21: H | X21: Title companies | Y21: H | Z21: H | AA21: N | AB21: L | AD21: YES | AE21: 30 DAYS | AF21: Personally deliver the lien or mortgage to the county | AG21: X | AI21: X | AJ21: X | AL21: X | AM21: X | AN21: X | AO21: X | BO21: X | BZ21: X | CN21: X | CY21: X | DN21: X | DP21: C | DW21: YES | DX21: YES | DY21: YES | DZ21: NO | EA21: YES | EB21: Title Companies | EC21: List of specified title companies
B22: Credit | C22: Loan Servicing | D22: Loan Documentation Preparation | E22: Preparation of loan documents for the bank. | F22: DAILY | G22: KBSC | I22: 1 DAY | J22: 1 DAY | K22: 4 HRS | L22: Could utilize lawyers for a day | M22: X | Q22: H | R22: H | S22: H | T22: L | U22: L | V22: H | W22: H | X22: High customer impact | Y22: H | Z22: N | AA22: N | AB22: M | AD22: YES | AE22: 1 DAY | AF22: Could call lawyers to draft a note | AG22: X | AL22: X | AM22: X | AN22: X | AO22: X | AP22: X | BK22: X | BO22: X | BZ22: X | CD22: X | CJ22: X | CN22: X | CY22: X | DC22: X | DN22: X | DP22: C | DW22: NO | DX22: YES | DY22: NO | DZ22: NO | EA22: YES | EB22: Wolters Kluwer | EC22: NO
B23: Credit | C23: Loan Servicing | D23: Loan Documentation Processing | E23: Process the executed loan documents. | F23: DAILY | G23: KBSC | I23: 1 DAY | J23: 1 DAY | K23: 2 DAYS | L23: Would wait for the system to be available | M23: X | Q23: L | R23: L | S23: L | T23: L | U23: L | V23: L | W23: L | X23: High customer impact | Y23: L | Z23: N | AA23: L | AB23: M | AD23: NO | AF23: Need to wait for systems but would be more of an internal impact | AG23: X | AL23: X | AN23: X | AO23: X | AP23: X | BB23: X | DP23: C | DW23: NO | DX23: YES | DY23: NO | DZ23: NO | EA23: NO | EB23: Fiserv | EC23: NO
B24: Deposit Operations | C24: Deposit Operations | D24: Account Maintenance | E24: Assist with debit cards, bill pay, online banking, statements | F24: DAILY | G24: KBSC | I24: 3 DAYS | J24: 3 DAYS | K24: 4 HRS | L24: Could do this process manually for a few days | N24: X | Q24: H | R24: H | S24: L | T24: L | U24: H | V24: H | W24: H | X24: High customer impact | Y24: L | Z24: M | AA24: M | AB24: M | AD24: YES | AE24: 3 DAYS | AF24: Manually write up changes, call on the phone | AG24: X | AI24: X | AJ24: X | AL24: X | AM24: X | AN24: X | AO24: X | AT24: X | AU24: X | BB24: X | BD24: X | BO24: X | BZ24: X | CN24: X | CY24: X | DN24: X | DP24: C | DW24: NO | DX24: YES | DY24: NO | DZ24: NO | EA24: NO | EB24: Fiserv, First Data | EC24: NO
B25: Deposit Operations | C25: Deposit Operations | D25: Levies, Garnishments | F25: WEEKLY | G25: KBSC | I25: 3 DAYS | J25: 3 DAYS | K25: 1 DAY | L25: This could be done manually | N25: X | Q25: H | R25: H | S25: L | T25: L | U25: H | V25: H | W25: H | X25: High customer impact | Y25: M | Z25: M | AA25: L | AB25: L | AD25: YES | AE25: 3 DAYS | AG25: X | AI25: X | AJ25: X | AL25: X | AM25: X | AN25: X | AO25: X | AT25: X | BB25: X | BO25: X | BZ25: X | CN25: X | CY25: X | DN25: X | DP25: C | DW25: YES | DX25: YES | DY25: NO | DZ25: NO | EA25: NO | EB25: Fiserv | EC25: NO
B26: Deposit Operations | C26: Deposit Operations | D26: ACH File and Funds Transfer Processing & Returns | E26: Client ACH file and funds transfers are received through business online banking/Premier ACH or ACH Manager. ACH returns are manually processed and tie in with the branch capture/cash-letter balancing and processing. | F26: DAILY | G26: KBSC | I26: 6 HRS | J26: 6 HRS | K26: 4 HRS | L26: Customer impact if wires can't be completed | M26: X | N26: X | O26: Consumer Banking | Q26: H | R26: H | S26: M | T26: N | U26: H | V26: H | W26: H | X26: Customer and revenue impacts | Y26: H | Z26: M | AA26: N | AB26: H | AD26: NO | AG26: X | AI26: X | AJ26: X | AL26: X | AM26: X | AN26: X | AO26: X | BB26: X | BI26: X | BO26: X | BV26: X | BZ26: X | CN26: X | CU26: X | CY26: X | DN26: X | DP26: C | DW26: NO | DX26: YES | DY26: NO | EA26: NO | EB26: Fiserv | EC26: Federal Reserve | ED26: ACH Client List and Processing Log | EE26: Written procedures | EG26: Assigned User Tokens and Codes
B27: Deposit Operations | C27: Deposit Operations | D27: Online Banking Maintenance & Support | E27: Provide support for online banking products and services. | F27: DAILY | G27: KBSC | I27: 1 DAY | J27: 1 DAY | K27: 4 HRS | L27: Customer impact if support isn't available for online banking services | N27: X | Q27: H | R27: H | S27: N | T27: N | U27: H | V27: L | W27: H | X27: Customer and revenue impacts | Y27: H | Z27: M | AA27: N | AB27: H | AD27: NO | AG27: X | AI27: X | AJ27: X | AL27: X | AM27: X | AN27: X | AO27: X | AR27: X | BB27: X | BO27: X | BZ27: X | CN27: X | CY27: X | DN27: X | DP27: C | DW27: YES | DX27: YES | DY27: YES | DZ27: YES | EA27: NO | EB27: Fiserv | EC27: NO | ED27: Online Banking Agreement Forms and Service Request Forms | EE27: Written procedures | EG27: Fiserv Printer P#?
B28: Deposit Operations | C28: Deposit Operations | D28: Large Item Returns | F28: DAILY | G28: KBSC | I28: 1 DAY | J28: 1 DAY | K28: 1 DAY | N28: X | Q28: H | R28: H | S28: M | T28: N | U28: L | V28: L | W28: H | X28: Customer impact | Y28: L | Z28: L | AA28: L | AB28: N | AD28: NO | AG28: X | AI28: X | AJ28: X | AL28: X | AM28: X | AN28: X | AO28: X | AT28: X | BA28: X | BB28: X | BI28: X | BO28: X | BV28: X | BZ28: X | CN28: X | CU28: X | CY28: X | DN28: X | DP28: C | DW28: YES | DX28: YES | DY28: NO | DZ28: NO | EA28: NO | EB28: Fiserv | EC28: NO | ED28: Return Processing Form,
B29: Deposit Operations | C29: Deposit Operations | D29: Daily processing of non-posts, chargeback's & return decision items | E29: Non-posts are exceptions or rejects from previous day's processing that need to be corrected and reposted. Returns decisions tie in with the Branch Capture processing and should be returned in a timely manner. | F29: DAILY | G29: KBSC | I29: 1 DAY | J29: 1 DAY | K29: 1 DAY | N29: X | Q29: H | R29: H | S29: M | T29: N | U29: L | V29: L | W29: H | X29: Customer impact | Y29: L | Z29: L | AA29: L | AB29: N | AD29: NO | AG29: X | AI29: X | AJ29: X | AL29: X | AM29: X | AN29: X | AO29: X | AT29: X | BA29: X | BB29: X | BI29: X | BO29: X | BV29: X | BZ29: X | CN29: X | CU29: X | CY29: X | DN29: X | DP29: C | DW29: YES | DX29: YES | DY29: NO | DZ29: NO | EA29: NO | EB29: Fiserv | EC29: NO | ED29: Return Processing Form, | EE29: Written procedures, IRD Print Paper | EG29: Unisys IRD Printer
B30: Deposit Operations | C30: Deposit Operations | D30: Wire Processing | E30: Daily processing of manual and online banking wire transfer requests. | F30: DAILY | G30: KBSC | I30: 30 DAYS | J30: 30 DAYS | K30: 1 DAY | L30: Wires could be called into the Fed | M30: X | N30: X | O30: Consumer Banking | Q30: H | R30: H | S30: N | T30: N | U30: H | V30: N | W30: H | X30: High customer and revenue impact | Y30: H | Z30: M | AA30: N | AB30: H | AD30: YES | AE30: 30 DAYS | AF30: Call them in to the Fed | AG30: X | AI30: X | AJ30: X | AL30: X | AM30: X | AN30: X | AO30: X | BB30: X | BM30: X | BN30: X | BO30: X | BX30: X | BY30: X | BZ30: X | CL30: X | CM30: X | CN30: X | CW30: X | CX30: X | CY30: X | DI30: X | DM30: X | DN30: X | DP30: C | DW30: NO | DX30: YES | DY30: NO | EA30: NO | EB30: Fiserv, Wells Fargo | EC30: Federal Reserve, Federal Home Loan Bank, Wells Fargo | ED30: Wire Balancing Form and Wire Forms | EE30: Written procedures | EG30: Assigned User Tokens and Codes
B31: Deposit Operations | C31: Deposit Operations | D31: Correspondent Daily Settlement | F31: DAILY | G31: KBSC | I31: 30 DAYS | J31: 30 DAYS | K31: 1 DAY | M31: X | N31: X | O31: Consumer Banking | Q31: H | R31: H | S31: N | T31: N | U31: H | V31: N | W31: H | X31: High customer and revenue impact | Y31: H | Z31: M | AA31: N | AB31: H | AD31: YES | AE31: 30 DAYS | AG31: X | AI31: X | AJ31: X | AL31: X | AM31: X | AN31: X | AO31: X | BB31: X | BM31: X | BN31: X | BO31: X | BX31: X | BY31: X | BZ31: X | CL31: X | CM31: X | CN31: X | CW31: X | CX31: X | CY31: X | DI31: X | DM31: X | DN31: X | DP31: C | DW31: NO | DX31: YES | DY31: NO | EA31: NO | EE31: Written procedures
B32: Deposit Operations | C32: Deposit Operations | D32: Lockbox Payment | F32: DAILY | G32: KBSC | I32: 30 DAYS | J32: 30 DAYS | K32: 1 DAY | M32: X | N32: X | O32: Consumer Banking | Q32: H | R32: H | S32: N | T32: N | U32: H | V32: N | W32: H | X32: High customer and revenue impact | Y32: H | Z32: M | AA32: N | AB32: H | AD32: YES | AE32: 30 DAYS | AG32: X | AI32: X | AJ32: X | AL32: X | AM32: X | AN32: X | AO32: X | BB32: X | BM32: X | BN32: X | BO32: X | BX32: X | BY32: X | BZ32: X | CL32: X | CM32: X | CN32: X | CW32: X | CX32: X | CY32: X | DI32: X | DM32: X | DN32: X | DP32: C | DW32: NO | DX32: YES | DY32: NO | EA32: NO | EE32: Written procedures
B33: Deposit Operations | C33: Deposit Operations | D33: Deposit Verifications | F33: DAILY | G33: KBSC | I33: 30 DAYS | J33: 30 DAYS | K33: 1 DAY | M33: X | N33: X | O33: Consumer Banking | Q33: H | R33: H | S33: N | T33: N | U33: H | V33: N | W33: H | X33: High customer and revenue impact | Y33: H | Z33: M | AA33: N | AB33: H | AD33: YES | AE33: 30 DAYS | AG33: X | AI33: X | AJ33: X | AL33: X | AM33: X | AN33: X | AO33: X | BB33: X | BM33: X | BN33: X | BO33: X | BX33: X | BY33: X | BZ33: X | CL33: X | CM33: X | CN33: X | CW33: X | CX33: X | CY33: X | DI33: X | DM33: X | DN33: X | DP33: C | DW33: NO | DX33: YES | DY33: NO | EA33: NO | EE33: Written procedures
B34: Deposit Operations | C34: Deposit Operations | D34: Misc. Research Requests, IRS Tax reporting, Unclaimed property | F34: DAILY | G34: KBSC | I34: 30 DAYS | J34: 30 DAYS | K34: 1 DAY | M34: X | N34: X | O34: Consumer Banking | Q34: H | R34: H | S34: N | T34: N | U34: H | V34: N | W34: H | X34: High customer and revenue impact | Y34: H | Z34: M | AA34: N | AB34: H | AD34: YES | AE34: 30 DAYS | AG34: X | AI34: X | AJ34: X | AL34: X | AM34: X | AN34: X | AO34: X | BB34: X | BM34: X | BN34: X | BO34: X | BX34: X | BY34: X | BZ34: X | CL34: X | CM34: X | CN34: X | CW34: X | CX34: X | CY34: X | DI34: X | DM34: X | DN34: X | DP34: C | DW34: NO | DX34: YES | DY34: NO | EA34: NO | EE34: Written procedures
B35: Deposit Operations | C35: Deposit Operations | D35: OFAC validation | F35: DAILY | G35: KBSC | I35: 30 DAYS | J35: 30 DAYS | K35: 1 DAY | M35: X | N35: X | O35: Consumer Banking | Q35: H | R35: H | S35: N | T35: N | U35: H | V35: N | W35: H | X35: High customer and revenue impact | Y35: H | Z35: M | AA35: N | AB35: H | AD35: YES | AE35: 30 DAYS | AG35: X | AI35: X | AJ35: X | AL35: X | AM35: X | AN35: X | AO35: X | BB35: X | BM35: X | BN35: X | BO35: X | BX35: X | BY35: X | BZ35: X | CL35: X | CM35: X | CN35: X | CW35: X | CX35: X | CY35: X | DI35: X | DM35: X | DN35: X | DP35: C | DW35: NO | DX35: YES | DY35: NO | EA35: NO | EE35: Written procedures
B36: Fee Based | C36: Cash Mgmt Sales | D36: Sales of Merchant Credit Card Processing | E36: Selling merchant credit cards and processing. | F36: DAILY | G36: ALL 20 | I36: 30 DAYS | J36: 30 DAYS | K36: 30 DAYS | L36: Could do this process manually or it could wait | N36: X | Q36: N | R36: N | S36: N | T36: N | U36: L | V36: N | W36: L | X36: This could be done manually | Y36: L | Z36: L | AA36: N | AB36: N | AD36: YES | AF36: Manual Process | AH36: X | AI36: X | AJ36: X | AL36: X | DP36: PU | DW36: YES | DX36: YES | DY36: YES | DZ36: YES | EA36: YES | EC36: NO
B37: Fee Based | C37: Cash Mgmt Sales | D37: Sales of Business Credit Cards | E37: Selling business credit cards. | F37: DAILY | G37: ALL 20 | I37: 30 DAYS | J37: 30 DAYS | K37: 30 DAYS | L37: Could do this process manually or it could wait | N37: X | Q37: N | R37: N | S37: N | T37: N | U37: L | V37: N | W37: L | X37: This could be done manually | Y37: L | Z37: L | AA37: N | AB37: N | AD37: YES | AF37: Manual Process | AH37: X | AI37: X | AJ37: X | AL37: X | DP37: PU | DW37: YES | DX37: YES | DY37: YES | DZ37: YES | EA37: YES | EB37: Elan Financial Services | EC37: NO
B38: Fee Based | C38: Cash Mgmt Sales | D38: Training of Commercial Banking Products and Services | E38: Train and implement Commercial Deposit Accounts, Cash Management products and services. | F38: DAILY | G38: ALL 20 | I38: 30 DAYS | J38: 30 DAYS | K38: 30 DAYS | L38: Could do this process manually or it could wait | N38: X | Q38: H | R38: H | S38: N | T38: N | U38: H | V38: N | W38: H | X38: This could be done manually | Y38: L | Z38: L | AA38: N | AB38: N | AD38: YES | AF38: Manual Process | AH38: X | AI38: X | AJ38: X | AL38: X | AM38: X | AN38: X | AO38: X | BO38: X | BZ38: X | CN38: X | CY38: X | DN38: X | DP38: PU | DW38: YES | DX38: YES | DY38: YES | DZ38: YES | EA38: YES
B39: Fee Based | C39: Insurance | D39: Sell Services | I39: 90 DAYS | J39: 90 DAYS | K39: 30 DAYS | M39: X | N39: X | O39: All | Q39: L | R39: L | S39: H | T39: L | U39: L | V39: M | W39: M | Y39: N | Z39: L | AA39: M | AB39: N | AD39: YES | AE39: 90 DAYS | AG39: X | AI39: X | AJ39: X | AL39: X | AM39: X | AN39: X | AO39: X | AP39: X | AT39: X | AU39: X | BB39: X | BI39: X | BO39: X | BV39: X | BZ39: X | CN39: X | CU39: X | CY39: X | DN39: X | DP39: PR | DW39: YES | DX39: YES | DY39: YES | DZ39: NO | EA39: YES
B40: Fee Based | C40: Investments | D40: Sell Services | I40: 90 DAYS | J40: 90 DAYS | K40: 30 DAYS | M40: X | N40: X | O40: All | Q40: L | R40: L | S40: H | T40: L | U40: L | V40: M | W40: M | Y40: N | Z40: L | AA40: M | AB40: N | AD40: YES | AE40: 90 DAYS | AG40: X | AI40: X | AJ40: X | AL40: X | AM40: X | AN40: X | AO40: X | AP40: X | AT40: X | AU40: X | BB40: X | BI40: X | BO40: X | BV40: X | BZ40: X | CN40: X | CU40: X | CY40: X | DN40: X | DP40: PR | DW40: YES | DX40: YES | DY40: YES | DZ40: NO | EA40: YES
...

Sheet Process Ideas
A1: Process examples
A2: FA | B2: Accounts payable
B3: Accounts receivable
B4: General ledger
B5: Financial reporting
A10: HR | B10: Benefits
B11: Recruiting
B12: Training
B13: Payroll
A18: Lending | B18: Application
B19: Underwriting
B20: Disbursing
B21: Servicing
A26: Operations | B26: Account maintenance
B27: Item processing
B28: Statement processing
B29: Electronic services
B30: ATM reconciliation
A35: Banking | B35: Open/close accounts
B36: Cash ordering
B37: Customer inquiries
B38: Teller transactions

Sheet Questions for Interview
A1: Ask during the BIA interview process
A2: Building loss, Data loss, Pandemic
B3: How have you done this process in the past when there were issues
B4: Who will/could do this if primary was gone for extended period of time
B5: What other locations can you do this - manual process or current process
B6: Who is your customer
B7: Don't assume the vendor will be available
A9: Cybersecurity Issues
